Workbook

Sheet Min. Curv
A1: Minimum curvature forward and backward implementation. | K1: Yellow are input fields
A2: Accompanies the document "SDU_wellbore_trajectory_calculations" | K2: Red column headers indicate final output
A3: Bert Kampes, 2019-08-23; updated 2020-01-21 for better handling ft survey with ftUS CRS and inverse min. curvature
A5: Directional survey observation references
B6: MD unit | E6: m | K6: i.e., the calculated local coordinates (n,e,d) will have the same unit
B7: AZ reference | E7: Grid North | K7: i.e., the calculated local coordinates (n,e) will be aligned the same (with Grid North of the projected CRS or True North)
B8: ZDP_height | E8: (see next page for more complete survey header) | K8: Not needed for min curvature calculations; but required metadata with the survey
A9: Well
B10: Name | E10: A008
B11: UWI | E11: 6081740479
A12: Wellbore
B13: Name | E13: A008 ST01BP01
B14: UWBI | E14: 608174047904
A15: MDINCAZ to wellbore local method | E15: Minimum curvature
A18: DIRECTIONAL SURVEY DATA (input M,I,A) | H18: MINIMUM CURVATURE (input MD,INC,AZ; output n,e,d) | S18: INVERSE MINIMUM CURVATURE (input MD1, I1, A1 and n,e,d; output MD,INC,AZ) | AH18: roundtrip error analysis
O19: =CONCATENATE("(oriented """,E7,""")") -> (oriented "Grid North") | AH19: =MAX(AH22:AH99999) -> 7.2759576e-12 | AI19: =MAX(AI22:AI99999) -> 2.310134e-09 | AJ19: =MAX(AJ22:AJ99999) -> 1.8317994e-06
A20: =CONCATENATE("MD [",$E6,"]") -> MD [m] | B20: INC [deg] | C20: AZ [deg] | E20: INC [rad] | F20: AZ [rad] | H20: Dogleg [rad] | I20: alt eq for DL | J20: =IF(LEFT(E$6,1)="m", "DLS [deg/30m]", "DLS [deg/100ft]") -> DLS [deg/30m] | K20: Ratio Factor | L20: =CONCATENATE("dn [",$E6,"]") -> dn [m] | M20: =CONCATENATE("de [",$E6,"]") -> de [m] | N20: =CONCATENATE("dd [",$E6,"]") -> dd [m] | O20: =CONCATENATE("n [",$E6,"]") -> n [m] | P20: =CONCATENATE("e [",$E6,"]") -> e [m] | Q20: =CONCATENATE("d [",$E6,"]") -> d [m] | S20: =CONCATENATE("dn [",$E6,"]") -> dn [m] | T20: =CONCATENATE("de [",$E6,"]") -> de [m] | U20: =CONCATENATE("dd [",$E6,"]") -> dd [m] | V20: =CONCATENATE("R [",$E6,"]") -> R [m] | W20: Dogleg [rad] | X20: Ratio Factor | Y20: =CONCATENATE("dM [",$E6,"]") -> dM [m] | Z20: INC [rad] | AA20: AZ_N [rad] | AB20: AZ_E [rad] | AC20: AZ [rad] | AD20: =CONCATENATE("MD [",$E6,"]") -> MD [m] | AE20: INC [deg] | AF20: AZ [deg] | AH20: error MD^ | AI20: error INC^ | AJ20: error AZ^
A21: 0 | B21: 0 | C21: 55.47 | E21: =RADIANS(B21) -> 0 | F21: =RADIANS(C21) -> 0.96813414 | O21: 0 | P21: 0 | Q21: 0 | Z21: =E21 -> 0 | AC21: =F21 -> 0.96813414 | AD21: =A21 -> 0 | AE21: =DEGREES(Z21) -> 0 | AF21: =MOD(DEGREES(AC21),360) -> 55.47
A22: 3137 | B22: 0 | C22: 55.47 | E22: =RADIANS(B22) -> 0 | F22: =RADIANS(C22) -> 0.96813414 | H22: =ACOS(MAX(-1,MIN(1, COS(E22-E21)-SIN(E21)*SIN(E22)*(1-COS(F22-F21))))) -> 0 | I22: =2*ASIN(SQRT( SIN((E22-E21)/2)^2 + SIN(E21)*SIN(E22)*SIN((F22-F21)/2)^2) ) -> 0 | J22: =IF(LEFT(E$6,1)="m", 30*DEGREES(H22)/(A22-A21), 100*DEGREES(H22)/(A22-A21)) -> 0 | K22: =IF(H22=0, 1, 2*TAN(H22/2)/H22) -> 1 | L22: =0.5*(A22-A21)*K22 * (SIN(E21)*COS(F21) + SIN(E22)*COS(F22)) -> 0 | M22: =0.5*(A22-A21)*K22 * (SIN(E21)*SIN(F21) + SIN(E22)*SIN(F22)) -> 0 | N22: =0.5*(A22-A21)*K22 * (COS(E21) + COS(E22)) -> 3137 | O22: =O21+L22 -> 0 | P22: =P21+M22 -> 0 | Q22: =Q21+N22 -> 3137 | S22: =O22-O21 -> 0 | T22: =P22-P21 -> 0 | U22: =Q22-Q21 -> 3137 | V22: =SQRT(S22^2+T22^2+U22^2) -> 3137 | W22: =2*ACOS(MAX(-1,MIN(1, (S22*SIN(Z21)*COS(AC21) + T22*SIN(Z21)*SIN(AC21) + U22*COS(Z21))/V22))) -> 0 | X22: =IF(W22=0, 1, 2*TAN(W22/2)/W22) -> 1 | Y22: =IF(W22=0, V22, 0.5*W22*V22/SIN(W22/2)) -> 3137 | Z22: =ACOS(MAX(-1,MIN(1, U22/(0.5*Y22*X22) - COS(Z21)))) -> 0 | AA22: =IF(Z22<0.000001, 0, ACOS(MAX(-1,MIN(1, (S22/(0.5*Y22*X22) - SIN(Z21)*COS(AC21))/SIN(Z22))))) -> 0 | AB22: =IF(Z22<0.000001, 0, ASIN(MAX(-1,MIN(1, (T22/(0.5*Y22*X22) - SIN(Z21)*SIN(AC21))/SIN(Z22))))) -> 0 | AC22: =IF(Z22<0.000001, 0, SIGN(AB22)*AA22) -> 0 | AD22: =AD21+Y22 -> 3137 | AE22: =DEGREES(Z22) -> 0 | AF22: =MOD(DEGREES(AC22),360) -> 0 | AH22: =ABS(AD22-A22) -> 0 | AI22: =ABS(AE22-B22) -> 0 | AJ22: =IF(B22=0, 0, ABS(AF22-C22)) -> 0
A23: 3150 | B23: 0.83 | C23: 55.47 | E23: =RADIANS(B23) -> 0.014486233 | F23: =RADIANS(C23) -> 0.96813414 | H23: =ACOS(MAX(-1,MIN(1, COS(E23-E22)-SIN(E22)*SIN(E23)*(1-COS(F23-F22))))) -> 0.014486233 | I23: =2*ASIN(SQRT( SIN((E23-E22)/2)^2 + SIN(E22)*SIN(E23)*SIN((F23-F22)/2)^2) ) -> 0.014486233 | J23: =IF(LEFT(E$6,1)="m", 30*DEGREES(H23)/(A23-A22), 100*DEGREES(H23)/(A23-A22)) -> 1.9153846 | K23: =IF(H23=0, 1, 2*TAN(H23/2)/H23) -> 1.0000175 | L23: =0.5*(A23-A22)*K23 * (SIN(E22)*COS(F22) + SIN(E23)*COS(F23)) -> 0.053372793 | M23: =0.5*(A23-A22)*K23 * (SIN(E22)*SIN(F22) + SIN(E23)*SIN(F23)) -> 0.077570852 | N23: =0.5*(A23-A22)*K23 * (COS(E22) + COS(E23)) -> 12.999545 | O23: =O22+L23 -> 0.053372793 | P23: =P22+M23 -> 0.077570852 | Q23: =Q22+N23 -> 3149.9995 | S23: =O23-O22 -> 0.053372793 | T23: =P23-P22 -> 0.077570852 | U23: =Q23-Q22 -> 12.999545 | V23: =SQRT(S23^2+T23^2+U23^2) -> 12.999886 | W23: =2*ACOS(MAX(-1,MIN(1, (S23*SIN(Z22)*COS(AC22) + T23*SIN(Z22)*SIN(AC22) + U23*COS(Z22))/V23))) -> 0.014486233 | X23: =IF(W23=0, 1, 2*TAN(W23/2)/W23) -> 1.0000175 | Y23: =IF(W23=0, V23, 0.5*W23*V23/SIN(W23/2)) -> 13 | Z23: =ACOS(MAX(-1,MIN(1, U23/(0.5*Y23*X23) - COS(Z22)))) -> 0.014486233 | AA23: =IF(Z23<0.000001, 0, ACOS(MAX(-1,MIN(1, (S23/(0.5*Y23*X23) - SIN(Z22)*COS(AC22))/SIN(Z23))))) -> 0.96813414 | AB23: =IF(Z23<0.000001, 0, ASIN(MAX(-1,MIN(1, (T23/(0.5*Y23*X23) - SIN(Z22)*SIN(AC22))/SIN(Z23))))) -> 0.96813414 | AC23: =IF(Z23<0.000001, 0, SIGN(AB23)*AA23) -> 0.96813414 | AD23: =AD22+Y23 -> 3150 | AE23: =DEGREES(Z23) -> 0.83 | AF23: =MOD(DEGREES(AC23),360) -> 55.47 | AH23: =ABS(AD23-A23) -> 0 | AI23: =ABS(AE23-B23) -> 3.5549341e-13 | AJ23: =IF(B23=0, 0, ABS(AF23-C23)) -> 1.6683543e-11
A24: 3175 | B24: 0.72 | C24: 56.8 | E24: =RADIANS(B24) -> 0.012566371 | F24: =RADIANS(C24) -> 0.99134702 | H24: =ACOS(MAX(-1,MIN(1, COS(E24-E23)-SIN(E23)*SIN(E24)*(1-COS(F24-F23))))) -> 0.0019452378 | I24: =2*ASIN(SQRT( SIN((E24-E23)/2)^2 + SIN(E23)*SIN(E24)*SIN((F24-F23)/2)^2) ) -> 0.0019452378 | J24: =IF(LEFT(E$6,1)="m", 30*DEGREES(H24)/(A24-A23), 100*DEGREES(H24)/(A24-A23)) -> 0.1337447 | K24: =IF(H24=0, 1, 2*TAN(H24/2)/H24) -> 1.0000003 | L24: =0.5*(A24-A23)*K24 * (SIN(E23)*COS(F23) + SIN(E24)*COS(F24)) -> 0.18864702 | M24: =0.5*(A24-A23)*K24 * (SIN(E23)*SIN(F23) + SIN(E24)*SIN(F24)) -> 0.28060737 | N24: =0.5*(A24-A23)*K24 * (COS(E23) + COS(E24)) -> 24.997709 | O24: =O23+L24 -> 0.24201981 | P24: =P23+M24 -> 0.35817822 | Q24: =Q23+N24 -> 3174.9973 | S24: =O24-O23 -> 0.18864702 | T24: =P24-P23 -> 0.28060737 | U24: =Q24-Q23 -> 24.997709 | V24: =SQRT(S24^2+T24^2+U24^2) -> 24.999996 | W24: =2*ACOS(MAX(-1,MIN(1, (S24*SIN(Z23)*COS(AC23) + T24*SIN(Z23)*SIN(AC23) + U24*COS(Z23))/V24))) -> 0.0019452378 | X24: =IF(W24=0, 1, 2*TAN(W24/2)/W24) -> 1.0000003 | Y24: =IF(W24=0, V24, 0.5*W24*V24/SIN(W24/2)) -> 25 | Z24: =ACOS(MAX(-1,MIN(1, U24/(0.5*Y24*X24) - COS(Z23)))) -> 0.012566371 | AA24: =IF(Z24<0.000001, 0, ACOS(MAX(-1,MIN(1, (S24/(0.5*Y24*X24) - SIN(Z23)*COS(AC23))/SIN(Z24))))) -> 0.99134702 | AB24: =IF(Z24<0.000001, 0, ASIN(MAX(-1,MIN(1, (T24/(0.5*Y24*X24) - SIN(Z23)*SIN(AC23))/SIN(Z24))))) -> 0.99134702 | AC24: =IF(Z24<0.000001, 0, SIGN(AB24)*AA24) -> 0.99134702 | AD24: =AD23+Y24 -> 3175 | AE24: =DEGREES(Z24) -> 0.72 | AF24: =MOD(DEGREES(AC24),360) -> 56.8 | AH24: =ABS(AD24-A24) -> 0 | AI24: =ABS(AE24-B24) -> 1.558198e-12 | AJ24: =IF(B24=0, 0, ABS(AF24-C24)) -> 8.1278984e-11
A25: 3200 | B25: 0.82 | C25: 66.83 | E25: =RADIANS(B25) -> 0.0143117 | F25: =RADIANS(C25) -> 1.1664035 | H25: =ACOS(MAX(-1,MIN(1, COS(E25-E24)-SIN(E24)*SIN(E25)*(1-COS(F25-F24))))) -> 0.0029228639 | I25: =2*ASIN(SQRT( SIN((E25-E24)/2)^2 + SIN(E24)*SIN(E25)*SIN((F25-F24)/2)^2) ) -> 0.0029228639 | J25: =IF(LEFT(E$6,1)="m", 30*DEGREES(H25)/(A25-A24), 100*DEGREES(H25)/(A25-A24)) -> 0.20096132 | K25: =IF(H25=0, 1, 2*TAN(H25/2)/H25) -> 1.0000007 | L25: =0.5*(A25-A24)*K25 * (SIN(E24)*COS(F24) + SIN(E25)*COS(F25)) -> 0.1563951 | M25: =0.5*(A25-A24)*K25 * (SIN(E24)*SIN(F24) + SIN(E25)*SIN(F25)) -> 0.29589651 | N25: =0.5*(A25-A24)*K25 * (COS(E24) + COS(E25)) -> 24.997751 | O25: =O24+L25 -> 0.39841491 | P25: =P24+M25 -> 0.65407473 | Q25: =Q24+N25 -> 3199.995 | S25: =O25-O24 -> 0.1563951 | T25: =P25-P24 -> 0.29589651 | U25: =Q25-Q24 -> 24.997751 | V25: =SQRT(S25^2+T25^2+U25^2) -> 24.999991 | W25: =2*ACOS(MAX(-1,MIN(1, (S25*SIN(Z24)*COS(AC24) + T25*SIN(Z24)*SIN(AC24) + U25*COS(Z24))/V25))) -> 0.0029228639 | X25: =IF(W25=0, 1, 2*TAN(W25/2)/W25) -> 1.0000007 | Y25: =IF(W25=0, V25, 0.5*W25*V25/SIN(W25/2)) -> 25 | Z25: =ACOS(MAX(-1,MIN(1, U25/(0.5*Y25*X25) - COS(Z24)))) -> 0.0143117 | AA25: =IF(Z25<0.000001, 0, ACOS(MAX(-1,MIN(1, (S25/(0.5*Y25*X25) - SIN(Z24)*COS(AC24))/SIN(Z25))))) -> 1.1664035 | AB25: =IF(Z25<0.000001, 0, ASIN(MAX(-1,MIN(1, (T25/(0.5*Y25*X25) - SIN(Z24)*SIN(AC24))/SIN(Z25))))) -> 1.1664035 | AC25: =IF(Z25<0.000001, 0, SIGN(AB25)*AA25) -> 1.1664035 | AD25: =AD24+Y25 -> 3200 | AE25: =DEGREES(Z25) -> 0.82 | AF25: =MOD(DEGREES(AC25),360) -> 66.83 | AH25: =ABS(AD25-A25) -> 0 | AI25: =ABS(AE25-B25) -> 1.0941248e-12 | AJ25: =IF(B25=0, 0, ABS(AF25-C25)) -> 3.3097081e-11
A26: 3225 | B26: 0.87 | C26: 68.67 | E26: =RADIANS(B26) -> 0.015184364 | F26: =RADIANS(C26) -> 1.1985176 | H26: =ACOS(MAX(-1,MIN(1, COS(E26-E25)-SIN(E25)*SIN(E26)*(1-COS(F26-F25))))) -> 0.0009927874 | I26: =2*ASIN(SQRT( SIN((E26-E25)/2)^2 + SIN(E25)*SIN(E26)*SIN((F26-F25)/2)^2) ) -> 0.0009927874 | J26: =IF(LEFT(E$6,1)="m", 30*DEGREES(H26)/(A26-A25), 100*DEGREES(H26)/(A26-A25)) -> 0.068259034 | K26: =IF(H26=0, 1, 2*TAN(H26/2)/H26) -> 1.0000001 | L26: =0.5*(A26-A25)*K26 * (SIN(E25)*COS(F25) + SIN(E26)*COS(F26)) -> 0.1394229 | M26: =0.5*(A26-A25)*K26 * (SIN(E25)*SIN(F25) + SIN(E26)*SIN(F26)) -> 0.34125748 | N26: =0.5*(A26-A25)*K26 * (COS(E25) + COS(E26)) -> 24.997281 | O26: =O25+L26 -> 0.53783781 | P26: =P25+M26 -> 0.99533221 | Q26: =Q25+N26 -> 3224.9923 | S26: =O26-O25 -> 0.1394229 | T26: =P26-P25 -> 0.34125748 | U26: =Q26-Q25 -> 24.997281 | V26: =SQRT(S26^2+T26^2+U26^2) -> 24.999999 | W26: =2*ACOS(MAX(-1,MIN(1, (S26*SIN(Z25)*COS(AC25) + T26*SIN(Z25)*SIN(AC25) + U26*COS(Z25))/V26))) -> 0.0009927874 | X26: =IF(W26=0, 1, 2*TAN(W26/2)/W26) -> 1.0000001 | Y26: =IF(W26=0, V26, 0.5*W26*V26/SIN(W26/2)) -> 25 | Z26: =ACOS(MAX(-1,MIN(1, U26/(0.5*Y26*X26) - COS(Z25)))) -> 0.015184364 | AA26: =IF(Z26<0.000001, 0, ACOS(MAX(-1,MIN(1, (S26/(0.5*Y26*X26) - SIN(Z25)*COS(AC25))/SIN(Z26))))) -> 1.1985176 | AB26: =IF(Z26<0.000001, 0, ASIN(MAX(-1,MIN(1, (T26/(0.5*Y26*X26) - SIN(Z25)*SIN(AC25))/SIN(Z26))))) -> 1.1985176 | AC26: =IF(Z26<0.000001, 0, SIGN(AB26)*AA26) -> 1.1985176 | AD26: =AD25+Y26 -> 3225 | AE26: =DEGREES(Z26) -> 0.87 | AF26: =MOD(DEGREES(AC26),360) -> 68.67 | AH26: =ABS(AD26-A26) -> 0 | AI26: =ABS(AE26-B26) -> 4.589551e-12 | AJ26: =IF(B26=0, 0, ABS(AF26-C26)) -> 1.1806378e-10
A27: 3250 | B27: 0.87 | C27: 70.62 | E27: =RADIANS(B27) -> 0.015184364 | F27: =RADIANS(C27) -> 1.2325515 | H27: =ACOS(MAX(-1,MIN(1, COS(E27-E26)-SIN(E26)*SIN(E27)*(1-COS(F27-F26))))) -> 0.00051673866 | I27: =2*ASIN(SQRT( SIN((E27-E26)/2)^2 + SIN(E26)*SIN(E27)*SIN((F27-F26)/2)^2) ) -> 0.00051673866 | J27: =IF(LEFT(E$6,1)="m", 30*DEGREES(H27)/(A27-A26), 100*DEGREES(H27)/(A27-A26)) -> 0.035528333 | K27: =IF(H27=0, 1, 2*TAN(H27/2)/H27) -> 1 | L27: =0.5*(A27-A26)*K27 * (SIN(E26)*COS(F26) + SIN(E27)*COS(F27)) -> 0.13201745 | M27: =0.5*(A27-A26)*K27 * (SIN(E26)*SIN(F26) + SIN(E27)*SIN(F27)) -> 0.3558394 | N27: =0.5*(A27-A26)*K27 * (COS(E26) + COS(E27)) -> 24.997119 | O27: =O26+L27 -> 0.66985526 | P27: =P26+M27 -> 1.3511716 | Q27: =Q26+N27 -> 3249.9894 | S27: =O27-O26 -> 0.13201745 | T27: =P27-P26 -> 0.3558394 | U27: =Q27-Q26 -> 24.997119 | V27: =SQRT(S27^2+T27^2+U27^2) -> 25 | W27: =2*ACOS(MAX(-1,MIN(1, (S27*SIN(Z26)*COS(AC26) + T27*SIN(Z26)*SIN(AC26) + U27*COS(Z26))/V27))) -> 0.00051673866 | X27: =IF(W27=0, 1, 2*TAN(W27/2)/W27) -> 1 | Y27: =IF(W27=0, V27, 0.5*W27*V27/SIN(W27/2)) -> 25 | Z27: =ACOS(MAX(-1,MIN(1, U27/(0.5*Y27*X27) - COS(Z26)))) -> 0.015184364 | AA27: =IF(Z27<0.000001, 0, ACOS(MAX(-1,MIN(1, (S27/(0.5*Y27*X27) - SIN(Z26)*COS(AC26))/SIN(Z27))))) -> 1.2325515 | AB27: =IF(Z27<0.000001, 0, ASIN(MAX(-1,MIN(1, (T27/(0.5*Y27*X27) - SIN(Z26)*SIN(AC26))/SIN(Z27))))) -> 1.2325515 | AC27: =IF(Z27<0.000001, 0, SIGN(AB27)*AA27) -> 1.2325515 | AD27: =AD26+Y27 -> 3250 | AE27: =DEGREES(Z27) -> 0.87 | AF27: =MOD(DEGREES(AC27),360) -> 70.62 | AH27: =ABS(AD27-A27) -> 0 | AI27: =ABS(AE27-B27) -> 3.7944092e-12 | AJ27: =IF(B27=0, 0, ABS(AF27-C27)) -> 8.7581498e-11
A28: 3275 | B28: 0.83 | C28: 70.15 | E28: =RADIANS(B28) -> 0.014486233 | F28: =RADIANS(C28) -> 1.2243485 | H28: =ACOS(MAX(-1,MIN(1, COS(E28-E27)-SIN(E27)*SIN(E28)*(1-COS(F28-F27))))) -> 0.00070865231 | I28: =2*ASIN(SQRT( SIN((E28-E27)/2)^2 + SIN(E27)*SIN(E28)*SIN((F28-F27)/2)^2) ) -> 0.00070865231 | J28: =IF(LEFT(E$6,1)="m", 30*DEGREES(H28)/(A28-A27), 100*DEGREES(H28)/(A28-A27)) -> 0.048723344 | K28: =IF(H28=0, 1, 2*TAN(H28/2)/H28) -> 1 | L28: =0.5*(A28-A27)*K28 * (SIN(E27)*COS(F27) + SIN(E28)*COS(F28)) -> 0.12446524 | M28: =0.5*(A28-A27)*K28 * (SIN(E27)*SIN(F27) + SIN(E28)*SIN(F28)) -> 0.34935626 | N28: =0.5*(A28-A27)*K28 * (COS(E27) + COS(E28)) -> 24.997248 | O28: =O27+L28 -> 0.79432051 | P28: =P27+M28 -> 1.7005279 | Q28: =Q27+N28 -> 3274.9867 | S28: =O28-O27 -> 0.12446524 | T28: =P28-P27 -> 0.34935626 | U28: =Q28-Q27 -> 24.997248 | V28: =SQRT(S28^2+T28^2+U28^2) -> 24.999999 | W28: =2*ACOS(MAX(-1,MIN(1, (S28*SIN(Z27)*COS(AC27) + T28*SIN(Z27)*SIN(AC27) + U28*COS(Z27))/V28))) -> 0.00070865231 | X28: =IF(W28=0, 1, 2*TAN(W28/2)/W28) -> 1 | Y28: =IF(W28=0, V28, 0.5*W28*V28/SIN(W28/2)) -> 25 | Z28: =ACOS(MAX(-1,MIN(1, U28/(0.5*Y28*X28) - COS(Z27)))) -> 0.014486233 | AA28: =IF(Z28<0.000001, 0, ACOS(MAX(-1,MIN(1, (S28/(0.5*Y28*X28) - SIN(Z27)*COS(AC27))/SIN(Z28))))) -> 1.2243485 | AB28: =IF(Z28<0.000001, 0, ASIN(MAX(-1,MIN(1, (T28/(0.5*Y28*X28) - SIN(Z27)*SIN(AC27))/SIN(Z28))))) -> 1.2243485 | AC28: =IF(Z28<0.000001, 0, SIGN(AB28)*AA28) -> 1.2243485 | AD28: =AD27+Y28 -> 3275 | AE28: =DEGREES(Z28) -> 0.83 | AF28: =MOD(DEGREES(AC28),360) -> 70.15 | AH28: =ABS(AD28-A28) -> 0 | AI28: =ABS(AE28-B28) -> 2.9890534e-12 | AJ28: =IF(B28=0, 0, ABS(AF28-C28)) -> 7.3924866e-11
A29: 3300 | B29: 0.78 | C29: 65.7 | E29: =RADIANS(B29) -> 0.013613568 | F29: =RADIANS(C29) -> 1.1466813 | H29: =ACOS(MAX(-1,MIN(1, COS(E29-E28)-SIN(E28)*SIN(E29)*(1-COS(F29-F28))))) -> 0.0013965926 | I29: =2*ASIN(SQRT( SIN((E29-E28)/2)^2 + SIN(E28)*SIN(E29)*SIN((F29-F28)/2)^2) ) -> 0.0013965926 | J29: =IF(LEFT(E$6,1)="m", 30*DEGREES(H29)/(A29-A28), 100*DEGREES(H29)/(A29-A28)) -> 0.096022637 | K29: =IF(H29=0, 1, 2*TAN(H29/2)/H29) -> 1.0000002 | L29: =0.5*(A29-A28)*K29 * (SIN(E28)*COS(F28) + SIN(E29)*COS(F29)) -> 0.13150955 | M29: =0.5*(A29-A28)*K29 * (SIN(E28)*SIN(F28) + SIN(E29)*SIN(F29)) -> 0.32540157 | N29: =0.5*(A29-A28)*K29 * (COS(E28) + COS(E29)) -> 24.997534 | O29: =O28+L29 -> 0.92583006 | P29: =P28+M29 -> 2.0259294 | Q29: =Q28+N29 -> 3299.9842 | S29: =O29-O28 -> 0.13150955 | T29: =P29-P28 -> 0.32540157 | U29: =Q29-Q28 -> 24.997534 | V29: =SQRT(S29^2+T29^2+U29^2) -> 24.999998 | W29: =2*ACOS(MAX(-1,MIN(1, (S29*SIN(Z28)*COS(AC28) + T29*SIN(Z28)*SIN(AC28) + U29*COS(Z28))/V29))) -> 0.0013965926 | X29: =IF(W29=0, 1, 2*TAN(W29/2)/W29) -> 1.0000002 | Y29: =IF(W29=0, V29, 0.5*W29*V29/SIN(W29/2)) -> 25 | Z29: =ACOS(MAX(-1,MIN(1, U29/(0.5*Y29*X29) - COS(Z28)))) -> 0.013613568 | AA29: =IF(Z29<0.000001, 0, ACOS(MAX(-1,MIN(1, (S29/(0.5*Y29*X29) - SIN(Z28)*COS(AC28))/SIN(Z29))))) -> 1.1466813 | AB29: =IF(Z29<0.000001, 0, ASIN(MAX(-1,MIN(1, (T29/(0.5*Y29*X29) - SIN(Z28)*SIN(AC28))/SIN(Z29))))) -> 1.1466813 | AC29: =IF(Z29<0.000001, 0, SIGN(AB29)*AA29) -> 1.1466813 | AD29: =AD28+Y29 -> 3300 | AE29: =DEGREES(Z29) -> 0.78 | AF29: =MOD(DEGREES(AC29),360) -> 65.7 | AH29: =ABS(AD29-A29) -> 4.5474735e-13 | AI29: =ABS(AE29-B29) -> 6.3588024e-12 | AJ29: =IF(B29=0, 0, ABS(AF29-C29)) -> 2.1070434e-10
A30: 3325 | B30: 0.58 | C30: 60.97 | E30: =RADIANS(B30) -> 0.01012291 | F30: =RADIANS(C30) -> 1.0641272 | H30: =ACOS(MAX(-1,MIN(1, COS(E30-E29)-SIN(E29)*SIN(E30)*(1-COS(F30-F29))))) -> 0.0036226113 | I30: =2*ASIN(SQRT( SIN((E30-E29)/2)^2 + SIN(E29)*SIN(E30)*SIN((F30-F29)/2)^2) ) -> 0.0036226113 | J30: =IF(LEFT(E$6,1)="m", 30*DEGREES(H30)/(A30-A29), 100*DEGREES(H30)/(A30-A29)) -> 0.2490724 | K30: =IF(H30=0, 1, 2*TAN(H30/2)/H30) -> 1.0000011 | L30: =0.5*(A30-A29)*K30 * (SIN(E29)*COS(F29) + SIN(E30)*COS(F30)) -> 0.13142816 | M30: =0.5*(A30-A29)*K30 * (SIN(E29)*SIN(F29) + SIN(E30)*SIN(F30)) -> 0.26572581 | N30: =0.5*(A30-A29)*K30 * (COS(E29) + COS(E30)) -> 24.998229 | O30: =O29+L30 -> 1.0572582 | P30: =P29+M30 -> 2.2916553 | Q30: =Q29+N30 -> 3324.9824 | S30: =O30-O29 -> 0.13142816 | T30: =P30-P29 -> 0.26572581 | U30: =Q30-Q29 -> 24.998229 | V30: =SQRT(S30^2+T30^2+U30^2) -> 24.999986 | W30: =2*ACOS(MAX(-1,MIN(1, (S30*SIN(Z29)*COS(AC29) + T30*SIN(Z29)*SIN(AC29) + U30*COS(Z29))/V30))) -> 0.0036226113 | X30: =IF(W30=0, 1, 2*TAN(W30/2)/W30) -> 1.0000011 | Y30: =IF(W30=0, V30, 0.5*W30*V30/SIN(W30/2)) -> 25 | Z30: =ACOS(MAX(-1,MIN(1, U30/(0.5*Y30*X30) - COS(Z29)))) -> 0.01012291 | AA30: =IF(Z30<0.000001, 0, ACOS(MAX(-1,MIN(1, (S30/(0.5*Y30*X30) - SIN(Z29)*COS(AC29))/SIN(Z30))))) -> 1.0641272 | AB30: =IF(Z30<0.000001, 0, ASIN(MAX(-1,MIN(1, (T30/(0.5*Y30*X30) - SIN(Z29)*SIN(AC29))/SIN(Z30))))) -> 1.0641272 | AC30: =IF(Z30<0.000001, 0, SIGN(AB30)*AA30) -> 1.0641272 | AD30: =AD29+Y30 -> 3325 | AE30: =DEGREES(Z30) -> 0.58 | AF30: =MOD(DEGREES(AC30),360) -> 60.97 | AH30: =ABS(AD30-A30) -> 4.5474735e-13 | AI30: =ABS(AE30-B30) -> 4.5821125e-12 | AJ30: =IF(B30=0, 0, ABS(AF30-C30)) -> 2.5113422e-10
A31: 3350 | B31: 0.52 | C31: 66.2 | E31: =RADIANS(B31) -> 0.0090757121 | F31: =RADIANS(C31) -> 1.155408 | H31: =ACOS(MAX(-1,MIN(1, COS(E31-E30)-SIN(E30)*SIN(E31)*(1-COS(F31-F30))))) -> 0.0013643922 | I31: =2*ASIN(SQRT( SIN((E31-E30)/2)^2 + SIN(E30)*SIN(E31)*SIN((F31-F30)/2)^2) ) -> 0.0013643922 | J31: =IF(LEFT(E$6,1)="m", 30*DEGREES(H31)/(A31-A30), 100*DEGREES(H31)/(A31-A30)) -> 0.0938087 | K31: =IF(H31=0, 1, 2*TAN(H31/2)/H31) -> 1.0000002 | L31: =0.5*(A31-A30)*K31 * (SIN(E30)*COS(F30) + SIN(E31)*COS(F31)) -> 0.10718309 | M31: =0.5*(A31-A30)*K31 * (SIN(E30)*SIN(F30) + SIN(E31)*SIN(F31)) -> 0.21443467 | N31: =0.5*(A31-A30)*K31 * (COS(E30) + COS(E31)) -> 24.998849 | O31: =O30+L31 -> 1.1644413 | P31: =P30+M31 -> 2.5060899 | Q31: =Q30+N31 -> 3349.9813 | S31: =O31-O30 -> 0.10718309 | T31: =P31-P30 -> 0.21443467 | U31: =Q31-Q30 -> 24.998849 | V31: =SQRT(S31^2+T31^2+U31^2) -> 24.999998 | W31: =2*ACOS(MAX(-1,MIN(1, (S31*SIN(Z30)*COS(AC30) + T31*SIN(Z30)*SIN(AC30) + U31*COS(Z30))/V31))) -> 0.0013643922 | X31: =IF(W31=0, 1, 2*TAN(W31/2)/W31) -> 1.0000002 | Y31: =IF(W31=0, V31, 0.5*W31*V31/SIN(W31/2)) -> 25 | Z31: =ACOS(MAX(-1,MIN(1, U31/(0.5*Y31*X31) - COS(Z30)))) -> 0.0090757121 | AA31: =IF(Z31<0.000001, 0, ACOS(MAX(-1,MIN(1, (S31/(0.5*Y31*X31) - SIN(Z30)*COS(AC30))/SIN(Z31))))) -> 1.155408 | AB31: =IF(Z31<0.000001, 0, ASIN(MAX(-1,MIN(1, (T31/(0.5*Y31*X31) - SIN(Z30)*SIN(AC30))/SIN(Z31))))) -> 1.155408 | AC31: =IF(Z31<0.000001, 0, SIGN(AB31)*AA31) -> 1.155408 | AD31: =AD30+Y31 -> 3350 | AE31: =DEGREES(Z31) -> 0.52 | AF31: =MOD(DEGREES(AC31),360) -> 66.2 | AH31: =ABS(AD31-A31) -> 4.5474735e-13 | AI31: =ABS(AE31-B31) -> 1.1773915e-12 | AJ31: =IF(B31=0, 0, ABS(AF31-C31)) -> 5.7553962e-11
A32: 3375 | B32: 0.42 | C32: 67.5 | E32: =RADIANS(B32) -> 0.0073303829 | F32: =RADIANS(C32) -> 1.1780972 | H32: =ACOS(MAX(-1,MIN(1, COS(E32-E31)-SIN(E31)*SIN(E32)*(1-COS(F32-F31))))) -> 0.0017551128 | I32: =2*ASIN(SQRT( SIN((E32-E31)/2)^2 + SIN(E31)*SIN(E32)*SIN((F32-F31)/2)^2) ) -> 0.0017551128 | J32: =IF(LEFT(E$6,1)="m", 30*DEGREES(H32)/(A32-A31), 100*DEGREES(H32)/(A32-A31)) -> 0.12067267 | K32: =IF(H32=0, 1, 2*TAN(H32/2)/H32) -> 1.0000003 | L32: =0.5*(A32-A31)*K32 * (SIN(E31)*COS(F31) + SIN(E32)*COS(F32)) -> 0.080845041 | M32: =0.5*(A32-A31)*K32 * (SIN(E31)*SIN(F31) + SIN(E32)*SIN(F32)) -> 0.18845163 | N32: =0.5*(A32-A31)*K32 * (COS(E31) + COS(E32)) -> 24.999156 | O32: =O31+L32 -> 1.2452863 | P32: =P31+M32 -> 2.6945416 | Q32: =Q31+N32 -> 3374.9804 | S32: =O32-O31 -> 0.080845041 | T32: =P32-P31 -> 0.18845163 | U32: =Q32-Q31 -> 24.999156 | V32: =SQRT(S32^2+T32^2+U32^2) -> 24.999997 | W32: =2*ACOS(MAX(-1,MIN(1, (S32*SIN(Z31)*COS(AC31) + T32*SIN(Z31)*SIN(AC31) + U32*COS(Z31))/V32))) -> 0.0017551128 | X32: =IF(W32=0, 1, 2*TAN(W32/2)/W32) -> 1.0000003 | Y32: =IF(W32=0, V32, 0.5*W32*V32/SIN(W32/2)) -> 25 | Z32: =ACOS(MAX(-1,MIN(1, U32/(0.5*Y32*X32) - COS(Z31)))) -> 0.0073303829 | AA32: =IF(Z32<0.000001, 0, ACOS(MAX(-1,MIN(1, (S32/(0.5*Y32*X32) - SIN(Z31)*COS(AC31))/SIN(Z32))))) -> 1.1780972 | AB32: =IF(Z32<0.000001, 0, ASIN(MAX(-1,MIN(1, (T32/(0.5*Y32*X32) - SIN(Z31)*SIN(AC31))/SIN(Z32))))) -> 1.1780972 | AC32: =IF(Z32<0.000001, 0, SIGN(AB32)*AA32) -> 1.1780972 | AD32: =AD31+Y32 -> 3375 | AE32: =DEGREES(Z32) -> 0.42 | AF32: =MOD(DEGREES(AC32),360) -> 67.5 | AH32: =ABS(AD32-A32) -> 4.5474735e-13 | AI32: =ABS(AE32-B32) -> 2.1748159e-12 | AJ32: =IF(B32=0, 0, ABS(AF32-C32)) -> 1.229381e-10
A33: 3400 | B33: 0.32 | C33: 75.18 | E33: =RADIANS(B33) -> 0.0055850536 | F33: =RADIANS(C33) -> 1.3121385 | H33: =ACOS(MAX(-1,MIN(1, COS(E33-E32)-SIN(E32)*SIN(E33)*(1-COS(F33-F32))))) -> 0.0019443883 | I33: =2*ASIN(SQRT( SIN((E33-E32)/2)^2 + SIN(E32)*SIN(E33)*SIN((F33-F32)/2)^2) ) -> 0.0019443883 | J33: =IF(LEFT(E$6,1)="m", 30*DEGREES(H33)/(A33-A32), 100*DEGREES(H33)/(A33-A32)) -> 0.13368629 | K33: =IF(H33=0, 1, 2*TAN(H33/2)/H33) -> 1.0000003 | L33: =0.5*(A33-A32)*K33 * (SIN(E32)*COS(F32) + SIN(E33)*COS(F33)) -> 0.052921849 | M33: =0.5*(A33-A32)*K33 * (SIN(E32)*SIN(F32) + SIN(E33)*SIN(F33)) -> 0.1521446 | N33: =0.5*(A33-A32)*K33 * (COS(E32) + COS(E33)) -> 24.999477 | O33: =O32+L33 -> 1.2982082 | P33: =P32+M33 -> 2.8466861 | Q33: =Q32+N33 -> 3399.9799 | S33: =O33-O32 -> 0.052921849 | T33: =P33-P32 -> 0.1521446 | U33: =Q33-Q32 -> 24.999477 | V33: =SQRT(S33^2+T33^2+U33^2) -> 24.999996 | W33: =2*ACOS(MAX(-1,MIN(1, (S33*SIN(Z32)*COS(AC32) + T33*SIN(Z32)*SIN(AC32) + U33*COS(Z32))/V33))) -> 0.0019443883 | X33: =IF(W33=0, 1, 2*TAN(W33/2)/W33) -> 1.0000003 | Y33: =IF(W33=0, V33, 0.5*W33*V33/SIN(W33/2)) -> 25 | Z33: =ACOS(MAX(-1,MIN(1, U33/(0.5*Y33*X33) - COS(Z32)))) -> 0.0055850536 | AA33: =IF(Z33<0.000001, 0, ACOS(MAX(-1,MIN(1, (S33/(0.5*Y33*X33) - SIN(Z32)*COS(AC32))/SIN(Z33))))) -> 1.3121385 | AB33: =IF(Z33<0.000001, 0, ASIN(MAX(-1,MIN(1, (T33/(0.5*Y33*X33) - SIN(Z32)*SIN(AC32))/SIN(Z33))))) -> 1.3121385 | AC33: =IF(Z33<0.000001, 0, SIGN(AB33)*AA33) -> 1.3121385 | AD33: =AD32+Y33 -> 3400 | AE33: =DEGREES(Z33) -> 0.32 | AF33: =MOD(DEGREES(AC33),360) -> 75.18 | AH33: =ABS(AD33-A33) -> 9.094947e-13 | AI33: =ABS(AE33-B33) -> 2.7297609e-12 | AJ33: =IF(B33=0, 0, ABS(AF33-C33)) -> 1.2978774e-10
... A233: 18587 | B233: 58.84 | C233: 63.02 | E233: =RADIANS(B233) -> 1.0269517 | F233: =RADIANS(C233) -> 1.0999065 | H233: =ACOS(MAX(-1,MIN(1, COS(E233-E232)-SIN(E232)*SIN(E233)*(1-COS(F233-F232))))) -> 0 | I233: =2*ASIN(SQRT( SIN((E233-E232)/2)^2 + SIN(E232)*SIN(E233)*SIN((F233-F232)/2)^2) ) -> 0 | J233: =IF(LEFT(E$6,1)="m", 30*DEGREES(H233)/(A233-A232), 100*DEGREES(H233)/(A233-A232)) -> 0 | K233: =IF(H233=0, 1, 2*TAN(H233/2)/H233) -> 1 | L233: =0.5*(A233-A232)*K233 * (SIN(E232)*COS(F232) + SIN(E233)*COS(F233)) -> 16.305457 | M233: =0.5*(A233-A232)*K233 * (SIN(E232)*SIN(F232) + SIN(E233)*SIN(F233)) -> 32.028895 | N233: =0.5*(A233-A232)*K233 * (COS(E232) + COS(E233)) -> 21.732049 | O233: =O232+L233 -> -7254.4151 | P233: =P232+M233 -> 2197.3371 | Q233: =Q232+N233 -> 12677.18 | S233: =O233-O232 -> 16.305457 | T233: =P233-P232 -> 32.028895 | U233: =Q233-Q232 -> 21.732049 | V233: =SQRT(S233^2+T233^2+U233^2) -> 42 | W233: =2*ACOS(MAX(-1,MIN(1, (S233*SIN(Z232)*COS(AC232) + T233*SIN(Z232)*SIN(AC232) + U233*COS(Z232))/V233))) -> 0 | X233: =IF(W233=0, 1, 2*TAN(W233/2)/W233) -> 1 | Y233: =IF(W233=0, V233, 0.5*W233*V233/SIN(W233/2)) -> 42 | Z233: =ACOS(MAX(-1,MIN(1, U233/(0.5*Y233*X233) - COS(Z232)))) -> 1.0269517 | AA233: =IF(Z233<0.000001, 0, ACOS(MAX(-1,MIN(1, (S233/(0.5*Y233*X233) - SIN(Z232)*COS(AC232))/SIN(Z233))))) -> 1.0999065 | AB233: =IF(Z233<0.000001, 0, ASIN(MAX(-1,MIN(1, (T233/(0.5*Y233*X233) - SIN(Z232)*SIN(AC232))/SIN(Z233))))) -> 1.0999065 | AC233: =IF(Z233<0.000001, 0, SIGN(AB233)*AA233) -> 1.0999065 | AD233: =AD232+Y233 -> 18587 | AE233: =DEGREES(Z233) -> 58.84 | AF233: =MOD(DEGREES(AC233),360) -> 63.02 | AH233: =ABS(AD233-A233) -> 7.2759576e-12 | AI233: =ABS(AE233-B233) -> 1.6306956e-11 | AJ233: =IF(B233=0, 0, ABS(AF233-C233)) -> 8.3915097e-12

Sheet GNL
A1: Wellbore Local to Geodetic Coordinates: Grid North Local method. Assumes input (n,e,d) are aligned with Grid North. | L1: Yellow are input fields (output from min. curvature with grid north azimuths)
A2: Accompanies the document "SDU_wellbore_trajectory_calculations" | L2: Red column headers indicate final output
A3: Bert Kampes, 2019-08-24
A5: Well | H5: Wellbore
B6: Well name | E6: A008 | I6: Wellbore name | L6: A008 ST01BP01
B7: UWI | E7: 6081740479 | I7: UWBI | L7: 608174047904
A9: Observation references
B10: MD unit | E10: ft | F10: 0.3048 | H10: i.e., the local coordinates (n,e,d) are in ft
B11: AZ reference | E11: Grid North | H11: i.e., the local coordinates (n,e) aligned with Grid North of the projected CRS
A13: VertCRS | E13: MSL height (ftUS)
B14: Vertical CRS unit | E14: ftUS | F14: =1200/3937 -> 0.30480061 | H14: Conversion factor to meters
B15: Ground Level elevation | E15: 0 | F15: =E14 -> ftUS
B16: ZDP_offset_from_ground_level | E16: 192 | F16: =E14 -> ftUS
B17: ZDP_height | E17: =E15+E16 -> 192 | F17: =E14 -> ftUS
A19: ProjCRS | E19: NAD27 / BLM 16N (ftUS) [EPSG::32066]
B20: Projected CRS unit | E20: ftUS | F20: =1200/3937 -> 0.30480061 | H20: Conversion factor to meters
B21: WRP_Northing | E21: 10229028 | F21: =E20 -> ftUS
B22: WRP_Easting | E22: 924348.57 | F22: =E20 -> ftUS
B23: Grid convergence at WRP | E23: -1.05 | F23: deg | H23: This should not used. In case the AZ would be referenced to TN then the inputs to the minimum curvature algorith would be re-referenced to GN before applying min. curvature. However, it is possible to rereference the (n,e) using a 2D rotation matrix.
B24: Point scale factor at WRP | E24: 1.000188 | F24: [unitless] | H24: Optionally used to scale the local coordinates in the GNL algorithm if psf_flag=1. Assumed is that the same scale factor in N and E applies (i.e., that a conformal map projection is used)
A26: Wellbore local to geodetic method | E26: GNL (EPSG code 1077)
B27: psf_flag | E27: 1 | H27: 0: do not apply point scale factor; 1: apply constant.
B28: dcf_flag | E28: 0 | H28: 0: do not apply depth correction factor;
AG30: fwd<>bck
D31: Local coordinates (input n,e,d) | L31: GNL method (input: "Grid" n,e,d, psf_flag; output N,E,D) | T31: diff | V31: INVERSE GNL (input N,E,D, psf_flag, units of (N,E), D, and (n,e,d); output n,e,d) | AG31: error analysis
A32: (copy of input survey in 1 table) | D32: (oriented "grid north") | H32: (local coordinates in output units) | L32: (psf_flag=0 : no scaling applied) | P32: (psf_flag=1 : constant scaling applied) | V32: (psf_flag=0 : no scaling applied) | Z32: (psf_flag=1 : constant scaling applied) | AG32: =MAX(AG34:AG150) -> 9.2672469e-10
A33: =CONCATENATE("MD [",$E10,"]") -> MD [ft] | B33: INC [deg] | C33: AZ [deg] | D33: =CONCATENATE("n [",$E10,"]") -> n [ft] | E33: =CONCATENATE("e [",$E10,"]") -> e [ft] | F33: =CONCATENATE("d [",$E10,"]") -> d [ft] | H33: =CONCATENATE("n [",$E20,"]") -> n [ftUS] | I33: =CONCATENATE("e [",$E20,"]") -> e [ftUS] | J33: =CONCATENATE("d [",$E14,"]") -> d [ftUS] | L33: =CONCATENATE("N [",$E20,"]") -> N [ftUS] | M33: =CONCATENATE("E [",$E20,"]") -> E [ftUS] | N33: =CONCATENATE("D [",$E14,"]") -> D [ftUS] | P33: =CONCATENATE("N [",$E20,"]") -> N [ftUS] | Q33: =CONCATENATE("E [",$E20,"]") -> E [ftUS] | R33: =CONCATENATE("D [",$E14,"]") -> D [ftUS] | T33: =CONCATENATE("r [",$E20,"]") -> r [ftUS] | V33: =CONCATENATE("n [",$E20,"]") -> n [ftUS] | W33: =CONCATENATE("e [",$E20,"]") -> e [ftUS] | X33: =CONCATENATE("d [",$E14,"]") -> d [ftUS] | Z33: =CONCATENATE("n [",$E20,"]") -> n [ftUS] | AA33: =CONCATENATE("e [",$E20,"]") -> e [ftUS] | AB33: =CONCATENATE("d [",$E14,"]") -> d [ftUS] | AC33: =CONCATENATE("n [",$E10,"]") -> n [ft] | AD33: =CONCATENATE("e [",$E10,"]") -> e [ft] | AE33: =CONCATENATE("d [",$E10,"]") -> d [ft] | AG33: error
A34: 0 | B34: 0 | C34: 0 | D34: 0 | E34: 0 | F34: 0 | H34: =D34*F$10/F$20 -> 0 | I34: =E34*F$10/F$20 -> 0 | J34: =F34*F$10/F$14 -> 0 | L34: =E$21 + H34 -> 10229028 | M34: =E$22 + I34 -> 924348.57 | N34: =J34 - E$17 -> -192 | P34: =E$21 + E$24*H34 -> 10229028 | Q34: =E$22 + E$24*I34 -> 924348.57 | R34: =N34 - H$17 -> -192 | T34: =SQRT(SUMSQ(P34-L34,Q34-M34)) -> 0 | V34: =L34 - E$21 -> 0 | W34: =M34 - E$22 -> 0 | X34: =N34 + E$17 -> 0 | Z34: =(P34 - E$21) / E$24 -> 0 | AA34: =(Q34 - E$22) / E$24 -> 0 | AB34: =R34 + E$17 -> 0 | AC34: =Z34*F$20/F$10 -> 0 | AD34: =AA34*F$20/F$10 -> 0 | AE34: =AB34*F$14/F$10 -> 0 | AG34: =SQRT(SUMSQ(AC34-D34,AD34-E34,AE34-F34)) -> 0
A35: 30 | B35: 0.8 | C35: 87 | D35: 0 | E35: 0 | F35: 3137 | H35: =D35*F$10/F$20 -> 0 | I35: =E35*F$10/F$20 -> 0 | J35: =F35*F$10/F$14 -> 3136.9937 | L35: =E$21 + H35 -> 10229028 | M35: =E$22 + I35 -> 924348.57 | N35: =J35 - E$17 -> 2944.9937 | P35: =E$21 + E$24*H35 -> 10229028 | Q35: =E$22 + E$24*I35 -> 924348.57 | R35: =N35 - H$17 -> 2944.9937 | T35: =SQRT(SUMSQ(P35-L35,Q35-M35)) -> 0 | V35: =L35 - E$21 -> 0 | W35: =M35 - E$22 -> 0 | X35: =N35 + E$17 -> 3136.9937 | Z35: =(P35 - E$21) / E$24 -> 0 | AA35: =(Q35 - E$22) / E$24 -> 0 | AB35: =R35 + E$17 -> 3136.9937 | AC35: =Z35*F$20/F$10 -> 0 | AD35: =AA35*F$20/F$10 -> 0 | AE35: =AB35*F$14/F$10 -> 3137 | AG35: =SQRT(SUMSQ(AC35-D35,AD35-E35,AE35-F35)) -> 0
A36: 60 | B36: 0.9 | C36: 110 | D36: 0.053372793 | E36: 0.077570852 | F36: 3149.9995 | H36: =D36*F$10/F$20 -> 0.053372686 | I36: =E36*F$10/F$20 -> 0.077570697 | J36: =F36*F$10/F$14 -> 3149.9932 | L36: =E$21 + H36 -> 10229028 | M36: =E$22 + I36 -> 924348.65 | N36: =J36 - E$17 -> 2957.9932 | P36: =E$21 + E$24*H36 -> 10229028 | Q36: =E$22 + E$24*I36 -> 924348.65 | R36: =N36 - H$17 -> 2957.9932 | T36: =SQRT(SUMSQ(P36-L36,Q36-M36)) -> 1.7701784e-05 | V36: =L36 - E$21 -> 0.053372687 | W36: =M36 - E$22 -> 0.077570697 | X36: =N36 + E$17 -> 3149.9932 | Z36: =(P36 - E$21) / E$24 -> 0.053372687 | AA36: =(Q36 - E$22) / E$24 -> 0.077570697 | AB36: =R36 + E$17 -> 3149.9932 | AC36: =Z36*F$20/F$10 -> 0.053372793 | AD36: =AA36*F$20/F$10 -> 0.077570852 | AE36: =AB36*F$14/F$10 -> 3149.9995 | AG36: =SQRT(SUMSQ(AC36-D36,AD36-E36,AE36-F36)) -> 9.0383261e-10
A37: 90 | B37: 0.6 | C37: 185 | D37: 0.24201981 | E37: 0.35817822 | F37: 3174.9973 | H37: =D37*F$10/F$20 -> 0.24201933 | I37: =E37*F$10/F$20 -> 0.3581775 | J37: =F37*F$10/F$14 -> 3174.9909 | L37: =E$21 + H37 -> 10229029 | M37: =E$22 + I37 -> 924348.93 | N37: =J37 - E$17 -> 2982.9909 | P37: =E$21 + E$24*H37 -> 10229029 | Q37: =E$22 + E$24*I37 -> 924348.93 | R37: =N37 - H$17 -> 2982.9909 | T37: =SQRT(SUMSQ(P37-L37,Q37-M37)) -> 8.1267899e-05 | V37: =L37 - E$21 -> 0.24201933 | W37: =M37 - E$22 -> 0.3581775 | X37: =N37 + E$17 -> 3174.9909 | Z37: =(P37 - E$21) / E$24 -> 0.24201932 | AA37: =(Q37 - E$22) / E$24 -> 0.3581775 | AB37: =R37 + E$17 -> 3174.9909 | AC37: =Z37*F$20/F$10 -> 0.24201981 | AD37: =AA37*F$20/F$10 -> 0.35817822 | AE37: =AB37*F$14/F$10 -> 3174.9973 | AG37: =SQRT(SUMSQ(AC37-D37,AD37-E37,AE37-F37)) -> 4.3041838e-10
A38: 120 | B38: 0.8 | C38: 221.5 | D38: 0.39841491 | E38: 0.65407473 | F38: 3199.995 | H38: =D38*F$10/F$20 -> 0.39841411 | I38: =E38*F$10/F$20 -> 0.65407342 | J38: =F38*F$10/F$14 -> 3199.9886 | L38: =E$21 + H38 -> 10229029 | M38: =E$22 + I38 -> 924349.22 | N38: =J38 - E$17 -> 3007.9886 | P38: =E$21 + E$24*H38 -> 10229029 | Q38: =E$22 + E$24*I38 -> 924349.22 | R38: =N38 - H$17 -> 3007.9886 | T38: =SQRT(SUMSQ(P38-L38,Q38-M38)) -> 0.00014398158 | V38: =L38 - E$21 -> 0.39841411 | W38: =M38 - E$22 -> 0.65407342 | X38: =N38 + E$17 -> 3199.9886 | Z38: =(P38 - E$21) / E$24 -> 0.39841411 | AA38: =(Q38 - E$22) / E$24 -> 0.65407342 | AB38: =R38 + E$17 -> 3199.9886 | AC38: =Z38*F$20/F$10 -> 0.39841491 | AD38: =AA38*F$20/F$10 -> 0.65407473 | AE38: =AB38*F$14/F$10 -> 3199.995 | AG38: =SQRT(SUMSQ(AC38-D38,AD38-E38,AE38-F38)) -> 4.1780813e-10
A39: 150 | B39: 0.5 | C39: 180.4 | D39: 0.53783781 | E39: 0.99533221 | F39: 3224.9923 | H39: =D39*F$10/F$20 -> 0.53783674 | I39: =E39*F$10/F$20 -> 0.99533022 | J39: =F39*F$10/F$14 -> 3224.9858 | L39: =E$21 + H39 -> 10229029 | M39: =E$22 + I39 -> 924349.57 | N39: =J39 - E$17 -> 3032.9858 | P39: =E$21 + E$24*H39 -> 10229029 | Q39: =E$22 + E$24*I39 -> 924349.57 | R39: =N39 - H$17 -> 3032.9858 | T39: =SQRT(SUMSQ(P39-L39,Q39-M39)) -> 0.00021269287 | V39: =L39 - E$21 -> 0.53783674 | W39: =M39 - E$22 -> 0.99533022 | X39: =N39 + E$17 -> 3224.9858 | Z39: =(P39 - E$21) / E$24 -> 0.53783673 | AA39: =(Q39 - E$22) / E$24 -> 0.99533022 | AB39: =R39 + E$17 -> 3224.9858 | AC39: =Z39*F$20/F$10 -> 0.53783781 | AD39: =AA39*F$20/F$10 -> 0.99533221 | AE39: =AB39*F$14/F$10 -> 3224.9923 | AG39: =SQRT(SUMSQ(AC39-D39,AD39-E39,AE39-F39)) -> 7.3250917e-10
A40: 154 | B40: 0.536 | C40: 183.985 | D40: 0.66985526 | E40: 1.3511716 | F40: 3249.9894 | H40: =D40*F$10/F$20 -> 0.66985392 | I40: =E40*F$10/F$20 -> 1.3511689 | J40: =F40*F$10/F$14 -> 3249.9829 | L40: =E$21 + H40 -> 10229029 | M40: =E$22 + I40 -> 924349.92 | N40: =J40 - E$17 -> 3057.9829 | P40: =E$21 + E$24*H40 -> 10229029 | Q40: =E$22 + E$24*I40 -> 924349.92 | R40: =N40 - H$17 -> 3057.9829 | T40: =SQRT(SUMSQ(P40-L40,Q40-M40)) -> 0.00028352295 | V40: =L40 - E$21 -> 0.66985392 | W40: =M40 - E$22 -> 1.3511689 | X40: =N40 + E$17 -> 3249.9829 | Z40: =(P40 - E$21) / E$24 -> 0.66985392 | AA40: =(Q40 - E$22) / E$24 -> 1.3511689 | AB40: =R40 + E$17 -> 3249.9829 | AC40: =Z40*F$20/F$10 -> 0.66985526 | AD40: =AA40*F$20/F$10 -> 1.3511716 | AE40: =AB40*F$14/F$10 -> 3249.9894 | AG40: =SQRT(SUMSQ(AC40-D40,AD40-E40,AE40-F40)) -> 1.4028465e-10
A41: 180 | B41: 0.8 | C41: 198.7 | D41: 0.79432051 | E41: 1.7005279 | F41: 3274.9867 | H41: =D41*F$10/F$20 -> 0.79431892 | I41: =E41*F$10/F$20 -> 1.7005245 | J41: =F41*F$10/F$14 -> 3274.9801 | L41: =E$21 + H41 -> 10229029 | M41: =E$22 + I41 -> 924350.27 | N41: =J41 - E$17 -> 3082.9801 | P41: =E$21 + E$24*H41 -> 10229029 | Q41: =E$22 + E$24*I41 -> 924350.27 | R41: =N41 - H$17 -> 3082.9801 | T41: =SQRT(SUMSQ(P41-L41,Q41-M41)) -> 0.00035285582 | V41: =L41 - E$21 -> 0.79431892 | W41: =M41 - E$22 -> 1.7005245 | X41: =N41 + E$17 -> 3274.9801 | Z41: =(P41 - E$21) / E$24 -> 0.79431892 | AA41: =(Q41 - E$22) / E$24 -> 1.7005245 | AB41: =R41 + E$17 -> 3274.9801 | AC41: =Z41*F$20/F$10 -> 0.79432051 | AD41: =AA41*F$20/F$10 -> 1.7005279 | AE41: =AB41*F$14/F$10 -> 3274.9867 | AG41: =SQRT(SUMSQ(AC41-D41,AD41-E41,AE41-F41)) -> 5.9536039e-10
A42: 210 | B42: 0.81 | C42: 217 | D42: 0.92583006 | E42: 2.0259294 | F42: 3299.9842 | H42: =D42*F$10/F$20 -> 0.92582821 | I42: =E42*F$10/F$20 -> 2.0259254 | J42: =F42*F$10/F$14 -> 3299.9776 | L42: =E$21 + H42 -> 10229029 | M42: =E$22 + I42 -> 924350.6 | N42: =J42 - E$17 -> 3107.9776 | P42: =E$21 + E$24*H42 -> 10229029 | Q42: =E$22 + E$24*I42 -> 924350.6 | R42: =N42 - H$17 -> 3107.9776 | T42: =SQRT(SUMSQ(P42-L42,Q42-M42)) -> 0.00041876012 | V42: =L42 - E$21 -> 0.92582821 | W42: =M42 - E$22 -> 2.0259254 | X42: =N42 + E$17 -> 3299.9776 | Z42: =(P42 - E$21) / E$24 -> 0.92582821 | AA42: =(Q42 - E$22) / E$24 -> 2.0259254 | AB42: =R42 + E$17 -> 3299.9776 | AC42: =Z42*F$20/F$10 -> 0.92583006 | AD42: =AA42*F$20/F$10 -> 2.0259294 | AE42: =AB42*F$14/F$10 -> 3299.9842 | AG42: =SQRT(SUMSQ(AC42-D42,AD42-E42,AE42-F42)) -> 1.223109e-10
A43: 240 | B43: 1 | C43: 224 | D43: 1.0572582 | E43: 2.2916553 | F43: 3324.9824 | H43: =D43*F$10/F$20 -> 1.0572561 | I43: =E43*F$10/F$20 -> 2.2916507 | J43: =F43*F$10/F$14 -> 3324.9758 | L43: =E$21 + H43 -> 10229029 | M43: =E$22 + I43 -> 924350.86 | N43: =J43 - E$17 -> 3132.9758 | P43: =E$21 + E$24*H43 -> 10229029 | Q43: =E$22 + E$24*I43 -> 924350.86 | R43: =N43 - H$17 -> 3132.9758 | T43: =SQRT(SUMSQ(P43-L43,Q43-M43)) -> 0.00047447039 | V43: =L43 - E$21 -> 1.0572561 | W43: =M43 - E$22 -> 2.2916507 | X43: =N43 + E$17 -> 3324.9758 | Z43: =(P43 - E$21) / E$24 -> 1.0572561 | AA43: =(Q43 - E$22) / E$24 -> 2.2916507 | AB43: =R43 + E$17 -> 3324.9758 | AC43: =Z43*F$20/F$10 -> 1.0572582 | AD43: =AA43*F$20/F$10 -> 2.2916553 | AE43: =AB43*F$14/F$10 -> 3324.9824 | AG43: =SQRT(SUMSQ(AC43-D43,AD43-E43,AE43-F43)) -> 2.6242362e-10
A44: 270 | B44: 0.7 | C44: 196.3 | D44: 1.1644413 | E44: 2.5060899 | F44: 3349.9813 | H44: =D44*F$10/F$20 -> 1.164439 | I44: =E44*F$10/F$20 -> 2.5060849 | J44: =F44*F$10/F$14 -> 3349.9746 | L44: =E$21 + H44 -> 10229030 | M44: =E$22 + I44 -> 924351.08 | N44: =J44 - E$17 -> 3157.9746 | P44: =E$21 + E$24*H44 -> 10229030 | Q44: =E$22 + E$24*I44 -> 924351.08 | R44: =N44 - H$17 -> 3157.9746 | T44: =SQRT(SUMSQ(P44-L44,Q44-M44)) -> 0.00051951935 | V44: =L44 - E$21 -> 1.164439 | W44: =M44 - E$22 -> 2.5060849 | X44: =N44 + E$17 -> 3349.9746 | Z44: =(P44 - E$21) / E$24 -> 1.164439 | AA44: =(Q44 - E$22) / E$24 -> 2.5060849 | AB44: =R44 + E$17 -> 3349.9746 | AC44: =Z44*F$20/F$10 -> 1.1644413 | AD44: =AA44*F$20/F$10 -> 2.5060899 | AE44: =AB44*F$14/F$10 -> 3349.9813 | AG44: =SQRT(SUMSQ(AC44-D44,AD44-E44,AE44-F44)) -> 2.4672118e-10
A45: 300 | B45: 0.7 | C45: 206 | D45: 1.2452863 | E45: 2.6945416 | F45: 3374.9804 | H45: =D45*F$10/F$20 -> 1.2452839 | I45: =E45*F$10/F$20 -> 2.6945362 | J45: =F45*F$10/F$14 -> 3374.9737 | L45: =E$21 + H45 -> 10229030 | M45: =E$22 + I45 -> 924351.26 | N45: =J45 - E$17 -> 3182.9737 | P45: =E$21 + E$24*H45 -> 10229030 | Q45: =E$22 + E$24*I45 -> 924351.27 | R45: =N45 - H$17 -> 3182.9737 | T45: =SQRT(SUMSQ(P45-L45,Q45-M45)) -> 0.00055805507 | V45: =L45 - E$21 -> 1.2452839 | W45: =M45 - E$22 -> 2.6945362 | X45: =N45 + E$17 -> 3374.9737 | Z45: =(P45 - E$21) / E$24 -> 1.2452839 | AA45: =(Q45 - E$22) / E$24 -> 2.6945362 | AB45: =R45 + E$17 -> 3374.9737 | AC45: =Z45*F$20/F$10 -> 1.2452863 | AD45: =AA45*F$20/F$10 -> 2.6945416 | AE45: =AB45*F$14/F$10 -> 3374.9804 | AG45: =SQRT(SUMSQ(AC45-D45,AD45-E45,AE45-F45)) -> 1.3386321e-10
... A246: 3356.6 | B246: 1.6 | C246: 301.8 | D246: -7254.4151 | E246: 2197.3371 | F246: 12677.18 | H246: =D246*F$10/F$20 -> -7254.4006 | I246: =E246*F$10/F$20 -> 2197.3327 | J246: =F246*F$10/F$14 -> 12677.155 | L246: =E$21 + H246 -> 10221774 | M246: =E$22 + I246 -> 926545.9 | N246: =J246 - E$17 -> 12485.155 | P246: =E$21 + E$24*H246 -> 10221773 | Q246: =E$22 + E$24*I246 -> 926546.32 | R246: =N246 - H$17 -> 12485.155 | T246: =SQRT(SUMSQ(P246-L246,Q246-M246)) -> 1.4250177 | V246: =L246 - E$21 -> -7254.4006 | W246: =M246 - E$22 -> 2197.3327 | X246: =N246 + E$17 -> 12677.155 | Z246: =(P246 - E$21) / E$24 -> -7254.4006 | AA246: =(Q246 - E$22) / E$24 -> 2197.3327 | AB246: =R246 + E$17 -> 12677.155 | AC246: =Z246*F$20/F$10 -> -7254.4151 | AD246: =AA246*F$20/F$10 -> 2197.3371 | AE246: =AB246*F$14/F$10 -> 12677.18 | AG246: =SQRT(SUMSQ(AC246-D246,AD246-E246,AE246-F246)) -> 7.5733116e-10

Sheet LMP
A1: Wellbore Local to Geodetic Coordinates: LMP method. Assumes input (n,e,d) are aligned with True North. | K1: Yellow are input fields
A2: Accompanies the document "SDU_wellbore_trajectory_calculations" | K2: Red column headers indicate final output
A3: Bert Kampes, 2019-08-24
A5: Well | K5: Geodetic parameters for NAD27
B6: Well name | E6: A008 | K6: a | L6: 6378206.4 | M6: [m] semi-major axis
B7: UWI | E7: 6081740479 | K7: 1/f | L7: 294.9787 | M7: [-] inverse flattening
A8: Wellbore | K8: b | L8: 6356583.8 | M8: [m] semi-minor axis
B9: Wellbore name | E9: A008 ST01BP01 | K9: e2 | L9: =2/L7-1/L7^2 -> 0.006768658 | M9: [-] squared eccentricity
B10: UWBI | E10: 608174047904
A12: Observation references
B13: MD unit | E13: ft | F13: 0.3048 | I13: i.e., the local coordinates (n,e,d) are in meters
B14: AZ reference | E14: True North | I14: i.e., the local coordinates (n,e) aligned with True North. In order to compare with the GNL method I compute AZ_TRUE=AZ_GRID+convergence and recomputed n,e,d listed here. Alternately the grid oriented (n,e) could have been rotated, but that is not the preferred workflow.
A16: VertCRS | E16: NAVD88 depth (ftUS)
B17: Vertical CRS unit | E17: ftUS | F17: =1200/3937 -> 0.30480061 | I17: Conversion factor to meters
B18: Ground Level elevation | E18: 0 | F18: =E17 -> ftUS
B19: ZDP_offset_from_ground_level | E19: 192 | F19: =E17 -> ftUS
B20: ZDP_height | E20: =E18+E19 -> 192 | F20: =E17 -> ftUS
A22: ProjCRS | E22: NAD27 / BLM 16N (ftUS) [EPSG::32066] | I22: (strictly speaking no projected CRS needs to be defined, but it is done here for comparing with GNL and because in practice a projected CRS will be used in the application)
B23: Projected CRS unit | E23: ftUS | F23: =1200/3937 -> 0.30480061 | I23: Conversion factor to meters
B24: WRP_Latitude | E24: 0 | F24: deg | G24: 28° 10' 10.463 N
B25: WRP_Longitude | E25: -89.222953 | F25: deg | G25: 89° 13' 22.631 W
B26: Grid convergence at WRP | E26: -1.05 | F26: deg | I26: This should not used. In case the AZ would be referenced to TN then the inputs to the minimum curvature algorith would be re-referenced to GN before applying min. curvature. However, it is possible to rereference the (n,e) using a 2D rotation matrix.
B27: Point scale factor at WRP | E27: 1.00019 | F27: [unitless] | I27: Optionally used to scale the local coordinates in the GNL algorithm if psf_flag=1. Assumed is that the same scale factor in N and E applies (i.e., that a conformal map projection is used)
A29: Wellbore local to geodetic method | E29: LMP (EPSG code 1076)
B30: dcf_flag | E30: 0 | I30: 0: do not apply depth correction factor;
W31: compared with GNL method psf_flag=1
W33: (diff with GNL tab output)
E34: Local coordinates (input n,e,d) | I34: LMP method (input: "True" n,e,d; output: Lat,Lon,D) | Q34: then converted to projected coordinates (N,E) with Blue Marble) | W34: error analysis LMP<>GNL
A35: (copy of input survey in 1 table) | E35: (oriented "true north") | L35: (dcf_flag=0 : no depth correction factor applied) | Q35: (converted with Blue Marble for comparison with GNL method) | W35: =MAX(W37:W153) -> 0.016672315 | X35: =MAX(X37:X153) -> 0.037059173
A36: =CONCATENATE("MD [",$E13,"]") -> MD [ft] | B36: INC [deg] | C36: AZ_GRID | D36: AZ_TRUE | E36: =CONCATENATE("n [",$E13,"]") -> n [ft] | F36: =CONCATENATE("e [",$E13,"]") -> e [ft] | G36: =CONCATENATE("d [",$E13,"]") -> d [ft] | I36: rho [m] | J36: nu [m] | L36: LAT [deg] | M36: LON [deg] | N36: =CONCATENATE("D [",$E17,"]") -> D [ftUS] | Q36: =CONCATENATE("N [",$E23,"]") -> N [ftUS] | R36: =CONCATENATE("E [",$E23,"]") -> E [ftUS] | T36: point scale f | U36: convergence | W36: error N [ftUS] | X36: error E [ftUS]
A37: 0 | B37: 0 | C37: 55.47 | D37: =C37+E$26 -> 54.42 | E37: 0 | F37: 0 | G37: 0 | I37: =+L$6*(1-L$9)/(1-L$9*SIN(RADIANS(E24))^2)^1.5 -> 6335034.5 | J37: =+L$6/SQRT(1-L$9*SIN(RADIANS(E24))^2) -> 6378206.4 | L37: =E24 + DEGREES((E37-0)*F$13/I37) -> 0 | M37: =E25 + DEGREES((F37-0)*F$13/(J37*COS(RADIANS(E24)))) -> -89.222953 | N37: =G37*F$13/F$17 - E$20 -> -192 | Q37: 10229028 | R37: 924348.56 | T37: 1.000188 | U37: -1.05 | W37: =ABS(Q37-GNL!P34) -> 0.0099999998 | X37: =ABS(R37-GNL!Q34) -> 0.0099999999
A38: 3137 | B38: 0 | C38: 55.47 | D38: =C38+E$26 -> 54.42 | E38: 0 | F38: 0 | G38: 3137 | I38: =+L$6*(1-L$9)/(1-L$9*SIN(RADIANS(L37))^2)^1.5 -> 6335034.5 | J38: =+L$6/SQRT(1-L$9*SIN(RADIANS(L37))^2) -> 6378206.4 | L38: =L37 + DEGREES((E38-E37)*F$13/I38) -> 0 | M38: =M37 + DEGREES((F38-F37)*F$13/(J38*COS(RADIANS(L37)))) -> -89.222953 | N38: =G38*F$13/F$17 - E$20 -> 2944.9937 | Q38: 10229028 | R38: 924348.56 | W38: =ABS(Q38-GNL!P35) -> 0.0099999998 | X38: =ABS(R38-GNL!Q35) -> 0.0099999999
A39: 3150 | B39: 0.83 | C39: 55.47 | D39: =C39+E$26 -> 54.42 | E39: 0.05 | F39: 0.08 | G39: 3149.9995 | I39: =+L$6*(1-L$9)/(1-L$9*SIN(RADIANS(L38))^2)^1.5 -> 6335034.5 | J39: =+L$6/SQRT(1-L$9*SIN(RADIANS(L38))^2) -> 6378206.4 | L39: =L38 + DEGREES((E39-E38)*F$13/I39) -> 1.3783472e-07 | M39: =M38 + DEGREES((F39-F38)*F$13/(J39*COS(RADIANS(L38)))) -> -89.222953 | N39: =G39*F$13/F$17 - E$20 -> 2957.9932 | Q39: 10229028 | R39: 924348.64 | W39: =ABS(Q39-GNL!P36) -> 0.01338272 | X39: =ABS(R39-GNL!Q36) -> 0.0075852806
A40: 3175 | B40: 0.72 | C40: 56.8 | D40: =C40+E$26 -> 55.75 | E40: 0.25 | F40: 0.35 | G40: 3174.9973 | I40: =+L$6*(1-L$9)/(1-L$9*SIN(RADIANS(L39))^2)^1.5 -> 6335034.5 | J40: =+L$6/SQRT(1-L$9*SIN(RADIANS(L39))^2) -> 6378206.4 | L40: =L39 + DEGREES((E40-E39)*F$13/I40) -> 6.8917358e-07 | M40: =M39 + DEGREES((F40-F39)*F$13/(J40*COS(RADIANS(L39)))) -> -89.222952 | N40: =G40*F$13/F$17 - E$20 -> 2982.9909 | Q40: 10229029 | R40: 924348.92 | W40: =ABS(Q40-GNL!P37) -> 0.012064824 | X40: =ABS(R40-GNL!Q37) -> 0.0082448412
A41: 3200 | B41: 0.82 | C41: 66.83 | D41: =C41+E$26 -> 65.78 | E41: 0.41 | F41: 0.65 | G41: 3199.995 | I41: =+L$6*(1-L$9)/(1-L$9*SIN(RADIANS(L40))^2)^1.5 -> 6335034.5 | J41: =+L$6/SQRT(1-L$9*SIN(RADIANS(L40))^2) -> 6378206.4 | L41: =L40 + DEGREES((E41-E40)*F$13/I41) -> 1.1302447e-06 | M41: =M40 + DEGREES((F41-F40)*F$13/(J41*COS(RADIANS(L40)))) -> -89.222951 | N41: =G41*F$13/F$17 - E$20 -> 3007.9886 | Q41: 10229029 | R41: 924349.21 | W41: =ABS(Q41-GNL!P38) -> 0.0084890127 | X41: =ABS(R41-GNL!Q38) -> 0.014196388
A42: 3225 | B42: 0.87 | C42: 68.67 | D42: =C42+E$26 -> 67.62 | E42: 0.56 | F42: 0.99 | G42: 3224.9923 | I42: =+L$6*(1-L$9)/(1-L$9*SIN(RADIANS(L41))^2)^1.5 -> 6335034.5 | J42: =+L$6/SQRT(1-L$9*SIN(RADIANS(L41))^2) -> 6378206.4 | L42: =L41 + DEGREES((E42-E41)*F$13/I42) -> 1.5437488e-06 | M42: =M41 + DEGREES((F42-F41)*F$13/(J42*COS(RADIANS(L41)))) -> -89.22295 | N42: =G42*F$13/F$17 - E$20 -> 3032.9858 | Q42: 10229029 | R42: 924349.55 | W42: =ABS(Q42-GNL!P39) -> 0.0079378467 | X42: =ABS(R42-GNL!Q39) -> 0.015517338
A43: 3250 | B43: 0.87 | C43: 70.62 | D43: =C43+E$26 -> 69.57 | E43: 0.69 | F43: 1.34 | G43: 3249.9894 | I43: =+L$6*(1-L$9)/(1-L$9*SIN(RADIANS(L42))^2)^1.5 -> 6335034.5 | J43: =+L$6/SQRT(1-L$9*SIN(RADIANS(L42))^2) -> 6378206.4 | L43: =L42 + DEGREES((E43-E42)*F$13/I43) -> 1.9021191e-06 | M43: =M42 + DEGREES((F43-F42)*F$13/(J43*COS(RADIANS(L42)))) -> -89.222949 | N43: =G43*F$13/F$17 - E$20 -> 3057.9829 | Q43: 10229029 | R43: 924349.91 | W43: =ABS(Q43-GNL!P40) -> 0.0099798553 | X43: =ABS(R43-GNL!Q40) -> 0.011422927
A44: 3275 | B44: 0.83 | C44: 70.15 | D44: =C44+E$26 -> 69.1 | E44: 0.83 | F44: 1.69 | G44: 3274.9867 | I44: =+L$6*(1-L$9)/(1-L$9*SIN(RADIANS(L43))^2)^1.5 -> 6335034.5 | J44: =+L$6/SQRT(1-L$9*SIN(RADIANS(L43))^2) -> 6378206.4 | L44: =L43 + DEGREES((E44-E43)*F$13/I44) -> 2.2880563e-06 | M44: =M43 + DEGREES((F44-F43)*F$13/(J44*COS(RADIANS(L43)))) -> -89.222948 | N44: =G44*F$13/F$17 - E$20 -> 3082.9801 | Q44: 10229029 | R44: 924350.26 | W44: =ABS(Q44-GNL!P41) -> 0.0044682492 | X44: =ABS(R44-GNL!Q41) -> 0.010844169
A45: 3300 | B45: 0.78 | C45: 65.7 | D45: =C45+E$26 -> 64.65 | E45: 0.96 | F45: 2.01 | G45: 3299.9842 | I45: =+L$6*(1-L$9)/(1-L$9*SIN(RADIANS(L44))^2)^1.5 -> 6335034.5 | J45: =+L$6/SQRT(1-L$9*SIN(RADIANS(L44))^2) -> 6378206.4 | L45: =L44 + DEGREES((E45-E44)*F$13/I45) -> 2.6464265e-06 | M45: =M44 + DEGREES((F45-F44)*F$13/(J45*COS(RADIANS(L44)))) -> -89.222947 | N45: =G45*F$13/F$17 - E$20 -> 3107.9776 | Q45: 10229029 | R45: 924350.58 | W45: =ABS(Q45-GNL!P42) -> 0.0060022622 | X45: =ABS(R45-GNL!Q42) -> 0.016306263
A46: 3325 | B46: 0.58 | C46: 60.97 | D46: =C46+E$26 -> 59.92 | E46: 1.1 | F46: 2.27 | G46: 3324.9824 | I46: =+L$6*(1-L$9)/(1-L$9*SIN(RADIANS(L45))^2)^1.5 -> 6335034.5 | J46: =+L$6/SQRT(1-L$9*SIN(RADIANS(L45))^2) -> 6378206.4 | L46: =L45 + DEGREES((E46-E45)*F$13/I46) -> 3.0323637e-06 | M46: =M45 + DEGREES((F46-F45)*F$13/(J46*COS(RADIANS(L45)))) -> -89.222947 | N46: =G46*F$13/F$17 - E$20 -> 3132.9758 | Q46: 10229029 | R46: 924350.85 | W46: =ABS(Q46-GNL!P43) -> 0.0074548628 | X46: =ABS(R46-GNL!Q43) -> 0.012081499
...

Sheet 2drot
A1: Wellbore Local to Geodetic Coordinates: Example of 2D rotation. This is only used as a test and demonstration here. It should not be used to implement rotation of local (n,e) coordinatates.
A2: Accompanies the document "SDU_wellbore_trajectory_calculations"
A3: Bert Kampes, 2019-08-24
A5: allthough the intention is to rotate using LMP input (change AZ_GN to AZ_TN before input into min curv) the alternative is to apply a simple 2D rotation matrix to the output.
A6: The disadvantage for LMP is that convergence is treated as a constant and not varied along the wellbore
B9: Grid convergence at WRP | E9: -1.05 | F9: deg | G9: AZ_TRUE = AZ_GRID + convergence | K9: [e_gn] = [cos(conv) -sin(conv)] * [e_tn] | O9: [e_tn] = [cos(-conv) -sin(-conv)] * [e_gn]
K10: [n_gn] [sin(conv) cos(conv)] [n_tn] | O10: [n_tn] [sin(-conv) cos(-conv)] [n_gn]
B11: copy of output of Min Curv using AZ_TRUE | F11: copy of output of Min Curv using AZ_TRUE
B12: Local coordinates | K12: ROT2D(TN to GN) | M12: error analysis | O12: ROT2D(GN to TN) | Q12: error analysis
A13: [deg] | B13: (oriented "grid north") | F13: (oriented "true north") | K13: (rotated from TN to GN) | M13: =MAX(M15:M131) -> 0.0085699489 | O13: (rotated from GN to TN) | Q13: =MAX(Q15:Q131) -> 0.0085699489
A14: AZ_GRID | B14: n [m] | C14: e [m] | E14: AZ_TRUE | F14: n [m] | G14: e [m] | J14: convergence [deg] | K14: n_gn | L14: e_gn | M14: error | O14: n_tn | P14: e_tn | Q14: error
A15: 55.47 | B15: 0 | C15: 0 | E15: 54.42 | F15: 0 | G15: 0 | J15: =E15-A15 -> -1.05 | K15: =SIN(RADIANS(J15))*G15 + COS(RADIANS(J15))*F15 -> 0 | L15: =COS(RADIANS(J15))*G15 + -SIN(RADIANS(J15))*F15 -> 0 | M15: =SQRT(SUMSQ(K15-B15,L15-C15)) -> 0 | O15: =SIN(RADIANS(-J15))*C15 + COS(RADIANS(-J15))*B15 -> 0 | P15: =COS(RADIANS(-J15))*C15 + -SIN(RADIANS(-J15))*B15 -> 0 | Q15: =SQRT(SUMSQ(O15-F15,P15-G15)) -> 0
A16: 55.47 | B16: 0 | C16: 0 | E16: 54.42 | F16: 0 | G16: 0 | J16: =E16-A16 -> -1.05 | K16: =SIN(RADIANS(J16))*G16 + COS(RADIANS(J16))*F16 -> 0 | L16: =COS(RADIANS(J16))*G16 + -SIN(RADIANS(J16))*F16 -> 0 | M16: =SQRT(SUMSQ(K16-B16,L16-C16)) -> 0 | O16: =SIN(RADIANS(-J16))*C16 + COS(RADIANS(-J16))*B16 -> 0 | P16: =COS(RADIANS(-J16))*C16 + -SIN(RADIANS(-J16))*B16 -> 0 | Q16: =SQRT(SUMSQ(O16-F16,P16-G16)) -> 0
A17: 55.47 | B17: 0.053372793 | C17: 0.077570852 | E17: 54.42 | F17: 0.05 | G17: 0.08 | J17: =E17-A17 -> -1.05 | K17: =SIN(RADIANS(J17))*G17 + COS(RADIANS(J17))*F17 -> 0.04852561 | L17: =COS(RADIANS(J17))*G17 + -SIN(RADIANS(J17))*F17 -> 0.080902813 | M17: =SQRT(SUMSQ(K17-B17,L17-C17)) -> 0.0058819338 | O17: =SIN(RADIANS(-J17))*C17 + COS(RADIANS(-J17))*B17 -> 0.054785311 | P17: =COS(RADIANS(-J17))*C17 + -SIN(RADIANS(-J17))*B17 -> 0.076579774 | Q17: =SQRT(SUMSQ(O17-F17,P17-G17)) -> 0.0058819338
A18: 56.8 | B18: 0.24201981 | C18: 0.35817822 | E18: 55.75 | F18: 0.25 | G18: 0.35 | J18: =E18-A18 -> -1.05 | K18: =SIN(RADIANS(J18))*G18 + COS(RADIANS(J18))*F18 -> 0.2435443 | L18: =COS(RADIANS(J18))*G18 + -SIN(RADIANS(J18))*F18 -> 0.35452246 | M18: =SQRT(SUMSQ(K18-B18,L18-C18)) -> 0.0039608867 | O18: =SIN(RADIANS(-J18))*C18 + COS(RADIANS(-J18))*B18 -> 0.24854276 | P18: =COS(RADIANS(-J18))*C18 + -SIN(RADIANS(-J18))*B18 -> 0.35368308 | Q18: =SQRT(SUMSQ(O18-F18,P18-G18)) -> 0.0039608867
A19: 66.83 | B19: 0.39841491 | C19: 0.65407473 | E19: 65.78 | F19: 0.41 | G19: 0.65 | J19: =E19-A19 -> -1.05 | K19: =SIN(RADIANS(J19))*G19 + COS(RADIANS(J19))*F19 -> 0.39801995 | L19: =COS(RADIANS(J19))*G19 + -SIN(RADIANS(J19))*F19 -> 0.65740408 | M19: =SQRT(SUMSQ(K19-B19,L19-C19)) -> 0.0033526918 | O19: =SIN(RADIANS(-J19))*C19 + COS(RADIANS(-J19))*B19 -> 0.41033388 | P19: =COS(RADIANS(-J19))*C19 + -SIN(RADIANS(-J19))*B19 -> 0.64666397 | Q19: =SQRT(SUMSQ(O19-F19,P19-G19)) -> 0.0033526918
A20: 68.67 | B20: 0.53783781 | C20: 0.99533221 | E20: 67.62 | F20: 0.56 | G20: 0.99 | J20: =E20-A20 -> -1.05 | K20: =SIN(RADIANS(J20))*G20 + COS(RADIANS(J20))*F20 -> 0.54176429 | L20: =COS(RADIANS(J20))*G20 + -SIN(RADIANS(J20))*F20 -> 1.0000957 | M20: =SQRT(SUMSQ(K20-B20,L20-C20)) -> 0.0061731925 | O20: =SIN(RADIANS(-J20))*C20 + COS(RADIANS(-J20))*B20 -> 0.55598689 | P20: =COS(RADIANS(-J20))*C20 + -SIN(RADIANS(-J20))*B20 -> 0.98530923 | Q20: =SQRT(SUMSQ(O20-F20,P20-G20)) -> 0.0061731925
A21: 70.62 | B21: 0.66985526 | C21: 1.3511716 | E21: 69.57 | F21: 0.69 | G21: 1.34 | J21: =E21-A21 -> -1.05 | K21: =SIN(RADIANS(J21))*G21 + COS(RADIANS(J21))*F21 -> 0.66532873 | L21: =COS(RADIANS(J21))*G21 + -SIN(RADIANS(J21))*F21 -> 1.3524192 | M21: =SQRT(SUMSQ(K21-B21,L21-C21)) -> 0.0046953132 | O21: =SIN(RADIANS(-J21))*C21 + COS(RADIANS(-J21))*B21 -> 0.69450291 | P21: =COS(RADIANS(-J21))*C21 + -SIN(RADIANS(-J21))*B21 -> 1.3386697 | Q21: =SQRT(SUMSQ(O21-F21,P21-G21)) -> 0.0046953132
A22: 70.15 | B22: 0.79432051 | C22: 1.7005279 | E22: 69.1 | F22: 0.83 | G22: 1.69 | J22: =E22-A22 -> -1.05 | K22: =SIN(RADIANS(J22))*G22 + COS(RADIANS(J22))*F22 -> 0.7988915 | L22: =COS(RADIANS(J22))*G22 + -SIN(RADIANS(J22))*F22 -> 1.7049259 | M22: =SQRT(SUMSQ(K22-B22,L22-C22)) -> 0.0063432432 | O22: =SIN(RADIANS(-J22))*C22 + COS(RADIANS(-J22))*B22 -> 0.82534918 | P22: =COS(RADIANS(-J22))*C22 + -SIN(RADIANS(-J22))*B22 -> 1.6856865 | Q22: =SQRT(SUMSQ(O22-F22,P22-G22)) -> 0.0063432432
A23: 65.7 | B23: 0.92583006 | C23: 2.0259294 | E23: 64.65 | F23: 0.96 | G23: 2.01 | J23: =E23-A23 -> -1.05 | K23: =SIN(RADIANS(J23))*G23 + COS(RADIANS(J23))*F23 -> 0.92300569 | L23: =COS(RADIANS(J23))*G23 + -SIN(RADIANS(J23))*F23 -> 2.0272544 | M23: =SQRT(SUMSQ(K23-B23,L23-C23)) -> 0.0031197181 | O23: =SIN(RADIANS(-J23))*C23 + COS(RADIANS(-J23))*B23 -> 0.96279961 | P23: =COS(RADIANS(-J23))*C23 + -SIN(RADIANS(-J23))*B23 -> 2.0086235 | Q23: =SQRT(SUMSQ(O23-F23,P23-G23)) -> 0.0031197181
A24: 60.97 | B24: 1.0572582 | C24: 2.2916553 | E24: 59.92 | F24: 1.1 | G24: 2.27 | J24: =E24-A24 -> -1.05 | K24: =SIN(RADIANS(J24))*G24 + COS(RADIANS(J24))*F24 -> 1.0582177 | L24: =COS(RADIANS(J24))*G24 + -SIN(RADIANS(J24))*F24 -> 2.2897763 | M24: =SQRT(SUMSQ(K24-B24,L24-C24)) -> 0.0021097957 | O24: =SIN(RADIANS(-J24))*C24 + COS(RADIANS(-J24))*B24 -> 1.0990751 | P24: =COS(RADIANS(-J24))*C24 + -SIN(RADIANS(-J24))*B24 -> 2.2718963 | Q24: =SQRT(SUMSQ(O24-F24,P24-G24)) -> 0.0021097957
A25: 66.2 | B25: 1.1644413 | C25: 2.5060899 | E25: 65.15 | F25: 1.21 | G25: 2.48 | J25: =E25-A25 -> -1.05 | K25: =SIN(RADIANS(J25))*G25 + COS(RADIANS(J25))*F25 -> 1.164351 | L25: =COS(RADIANS(J25))*G25 + -SIN(RADIANS(J25))*F25 -> 2.5017567 | M25: =SQRT(SUMSQ(K25-B25,L25-C25)) -> 0.0043341252 | O25: =SIN(RADIANS(-J25))*C25 + COS(RADIANS(-J25))*B25 -> 1.2101697 | P25: =COS(RADIANS(-J25))*C25 + -SIN(RADIANS(-J25))*B25 -> 2.4843308 | Q25: =SQRT(SUMSQ(O25-F25,P25-G25)) -> 0.0043341252
A26: 67.5 | B26: 1.2452863 | C26: 2.6945416 | E26: 66.45 | F26: 1.29 | G26: 2.67 | J26: =E26-A26 -> -1.05 | K26: =SIN(RADIANS(J26))*G26 + COS(RADIANS(J26))*F26 -> 1.2408558 | L26: =COS(RADIANS(J26))*G26 + -SIN(RADIANS(J26))*F26 -> 2.6931908 | M26: =SQRT(SUMSQ(K26-B26,L26-C26)) -> 0.0046318446 | O26: =SIN(RADIANS(-J26))*C26 + COS(RADIANS(-J26))*B26 -> 1.2944545 | P26: =COS(RADIANS(-J26))*C26 + -SIN(RADIANS(-J26))*B26 -> 2.6712693 | Q26: =SQRT(SUMSQ(O26-F26,P26-G26)) -> 0.0046318446
... A227: 63.02 | B227: -7254.4151 | C227: 2197.3371 | E227: 61.97 | F227: -7212.93 | G227: 2329.9 | J227: =E227-A227 -> -1.05 | K227: =SIN(RADIANS(J227))*G227 + COS(RADIANS(J227))*F227 -> -7254.4141 | L227: =COS(RADIANS(J227))*G227 + -SIN(RADIANS(J227))*F227 -> 2197.3323 | M227: =SQRT(SUMSQ(K227-B227,L227-C227)) -> 0.0048945831 | O227: =SIN(RADIANS(-J227))*C227 + COS(RADIANS(-J227))*B227 -> -7212.931 | P227: =COS(RADIANS(-J227))*C227 + -SIN(RADIANS(-J227))*B227 -> 2329.9048 | Q227: =SQRT(SUMSQ(O227-F227,P227-G227)) -> 0.0048945831

Sheet wrap azimuth
A1: Example how to wrap an angle difference passed its 360 discontinuity.
A2: Accompanies the document "SDU_wellbore_trajectory_calculations"
A3: Bert Kampes, 2021-03-27
A5: Given an azimuth angle in the domain from 0 to 360 degrees, the difference angle can be no larger than 180 degrees.
A6: Calculation such difference angle requires some if statements or can be resolved by complex math using Euler's formula.
A8: Example: The delta from A1=354 to A2=10 degrees equals 16 degrees.
A10: Calculation steps (given two angles in degrees in the interval from 0 to 360):
A11: 1 | B11: dA = A2-A1
A12: 2 | B12: if (dA >= 180) then dA -= 360
A13: 3 | B13: if (dA < 180) then dA += 360
A14: 4 | B14: dA = abs(dA) | E14: # optional in case only the magnitude of the difference is of interest
A16: Alternative implementation using some trigonometry on the complex unit circle
A17: 1 | B17: =DEGREES(ATAN2(COS(RADIANS(A2-A1)), SIN(RADIANS(A2-A1)))) | I17: # Note: MS Excel implements ATAN2(x,y) =ATAN(y/x) with switched arguments
A19: Example
B20: input: | C20: A1 | D20: 354 | E20: 185 | F20: 300 | G20: 354 | H20: 354 | I20: 0 | J20: 40
C21: A2 | D21: 4 | E21: 4 | F21: 4 | G21: 50 | H21: 4 | I21: 200 | J21: 4
B23: method 1: | C23: dA | D23: =D21-D20 -> -350 | E23: =E21-E20 -> -181 | F23: =F21-F20 -> -296 | G23: =G21-G20 -> -304 | H23: =H21-H20 -> -350 | I23: =I21-I20 -> 200 | J23: =J21-J20 -> -36
C24: if>180 | D24: =IF(D23>180, D23-360,D23) -> -350 | E24: =IF(E23>180, E23-360,E23) -> -181 | F24: =IF(F23>180, F23-360,F23) -> -296 | G24: =IF(G23>180, G23-360,G23) -> -304 | H24: =IF(H23>180, H23-360,H23) -> -350 | I24: =IF(I23>180, I23-360,I23) -> -160 | J24: =IF(J23>180, J23-360,J23) -> -36
C25: if<180 | D25: =IF(D24<-180, D24+360,D24) -> 10 | E25: =IF(E24<-180, E24+360,E24) -> 179 | F25: =IF(F24<-180, F24+360,F24) -> 64 | G25: =IF(G24<-180, G24+360,G24) -> 56 | H25: =IF(H24<-180, H24+360,H24) -> 10 | I25: =IF(I24<-180, I24+360,I24) -> -160 | J25: =IF(J24<-180, J24+360,J24) -> -36
B28: method 2: | C28: dA | D28: =DEGREES(ATAN2(COS(RADIANS(D21-D20)), SIN(RADIANS(D21-D20)))) -> 10 | E28: =DEGREES(ATAN2(COS(RADIANS(E21-E20)), SIN(RADIANS(E21-E20)))) -> 179 | F28: =DEGREES(ATAN2(COS(RADIANS(F21-F20)), SIN(RADIANS(F21-F20)))) -> 64 | G28: =DEGREES(ATAN2(COS(RADIANS(G21-G20)), SIN(RADIANS(G21-G20)))) -> 56 | H28: =DEGREES(ATAN2(COS(RADIANS(H21-H20)), SIN(RADIANS(H21-H20)))) -> 10 | I28: =DEGREES(ATAN2(COS(RADIANS(I21-I20)), SIN(RADIANS(I21-I20)))) -> -160 | J28: =DEGREES(ATAN2(COS(RADIANS(J21-J20)), SIN(RADIANS(J21-J20)))) -> -36

Sheet err
A1: Demonstration of simple method to evaluate the total position error when ignoring point scale factor and (varying) convergence.
A2: Accompanies the document "SDU_wellbore_trajectory_calculations"
A3: Bert Kampes, 2019-09-14
A5: Assume that the approximate Surface (SHL) and Bottom Hole Location (BHL) are knowm from computed trajectory or planning.
A6: Compute the point scale factor and convergence at both locations.
A7: 1. compute the distance without applying point scale factor (local distance)
A8: 2. compute the distance by applying a constant psf (for psf at SHL and BHL).
A9: 3. compute the perpendicular distance due to constant rotation by convergence (for conv at SHL and BHL).
A10: The correct grid distance (psf applied variable along path) is close to applying the average scale factor. Hence the error in calculated length is well approximated by the average difference between 1&2 above.
A11: The perpendicular error due to assuming a constant convergence is approximated by half the difference of 3 above (assuming linear change of convergence)
A12: The total error is the square root of the sum square of the 2 terms above (depth correction is computed below but ignored for the error as it is thought this correction should not be applied when drilling to a target picked from a volume).
A14: input
A15: calculated
A17: projCRS | B17: WGS 84 / UTM zone 15N | D17: Unit: | E17: m | G17: must convert below to meters!
A19: EXAMPLE A: 10km wellbore ~(70N, 90W) at edge of UTM zone | G19: EXAMPLE B: 10km wellbore ~(30N, 90W) at edge of UTM zone | M19: EXAMPLE C: Sakhalin well
A20: Conclusion: Change of convergence is main issue near pole | G20: Conclusion: scale is main issue, but convergence also | M20: Conclusion:
